2025-06-17 23:37:57 - errors - ERROR - ERROR HTTP_ERROR: Method Not Allowed | Info: Status: 405
2025-06-17 23:39:00 - errors - ERROR - ERROR HTTP_ERROR: Method Not Allowed | Info: Status: 405
2025-06-17 23:40:02 - errors - ERROR - ERROR HTTP_ERROR: Method Not Allowed | Info: Status: 405
2025-06-17 23:40:53 - errors - ERROR - ERROR API_REQUEST_FAILED: name 'ValidationException' is not defined | Info: Method: POST, Path: /api/v1/auth/login, Duration: 0.024s
2025-06-17 23:40:54 - errors - ERROR - ERROR INTERNAL_SERVER_ERROR: name 'ValidationException' is not defined | Info: Traceback:   + Exception Group Traceback (most recent call last):
  |   File "D:\Elearning\learning\.venv\Lib\site-packages\starlette\_utils.py", line 76, in collapse_excgroups
  |     yield
  |   File "D:\Elearning\learning\.venv\Lib\site-packages\starlette\middleware\base.py", line 177, in __call__
  |     async with anyio.create_task_group() as task_group:
  |                ~~~~~~~~~~~~~~~~~~~~~~~^^
  |   File "D:\Elearning\learning\.venv\Lib\site-packages\anyio\_backends\_asyncio.py", line 772, in __aexit__
  |     raise BaseExceptionGroup(
  |         "unhandled errors in a TaskGroup", self._exceptions
  |     ) from None
  | ExceptionGroup: unhandled errors in a TaskGroup (1 sub-exception)
  +-+---------------- 1 ----------------
    | Traceback (most recent call last):
    |   File "D:\Elearning\learning\.venv\Lib\site-packages\starlette\middleware\errors.py", line 165, in __call__
    |     await self.app(scope, receive, _send)
    |   File "D:\Elearning\learning\.venv\Lib\site-packages\starlette\middleware\base.py", line 176, in __call__
    |     with recv_stream, send_stream, collapse_excgroups():
    |                                    ~~~~~~~~~~~~~~~~~~^^
    |   File "C:\Program Files\Python313\Lib\contextlib.py", line 162, in __exit__
    |     self.gen.throw(value)
    |     ~~~~~~~~~~~~~~^^^^^^^
    |   File "D:\Elearning\learning\.venv\Lib\site-packages\starlette\_utils.py", line 82, in collapse_excgroups
    |     raise exc
    |   File "D:\Elearning\learning\.venv\Lib\site-packages\starlette\middleware\base.py", line 178, in __call__
    |     response = await self.dispatch_func(request, call_next)
    |                ^^^^^^^^^^^^^^^^^^^^^^^^^^^^^^^^^^^^^^^^^^^^
    |   File "D:\Elearning\learning\middleware\logging_middleware.py", line 33, in dispatch
    |     response = await call_next(request)
    |                ^^^^^^^^^^^^^^^^^^^^^^^^
    |   File "D:\Elearning\learning\.venv\Lib\site-packages\starlette\middleware\base.py", line 156, in call_next
    |     raise app_exc
    |   File "D:\Elearning\learning\.venv\Lib\site-packages\starlette\middleware\base.py", line 141, in coro
    |     await self.app(scope, receive_or_disconnect, send_no_error)
    |   File "D:\Elearning\learning\.venv\Lib\site-packages\starlette\middleware\cors.py", line 93, in __call__
    |     await self.simple_response(scope, receive, send, request_headers=headers)
    |   File "D:\Elearning\learning\.venv\Lib\site-packages\starlette\middleware\cors.py", line 144, in simple_response
    |     await self.app(scope, receive, send)
    |   File "D:\Elearning\learning\.venv\Lib\site-packages\starlette\middleware\exceptions.py", line 62, in __call__
    |     await wrap_app_handling_exceptions(self.app, conn)(scope, receive, send)
    |   File "D:\Elearning\learning\.venv\Lib\site-packages\starlette\_exception_handler.py", line 53, in wrapped_app
    |     raise exc
    |   File "D:\Elearning\learning\.venv\Lib\site-packages\starlette\_exception_handler.py", line 42, in wrapped_app
    |     await app(scope, receive, sender)
    |   File "D:\Elearning\learning\.venv\Lib\site-packages\starlette\routing.py", line 714, in __call__
    |     await self.middleware_stack(scope, receive, send)
    |   File "D:\Elearning\learning\.venv\Lib\site-packages\starlette\routing.py", line 734, in app
    |     await route.handle(scope, receive, send)
    |   File "D:\Elearning\learning\.venv\Lib\site-packages\starlette\routing.py", line 288, in handle
    |     await self.app(scope, receive, send)
    |   File "D:\Elearning\learning\.venv\Lib\site-packages\starlette\routing.py", line 76, in app
    |     await wrap_app_handling_exceptions(app, request)(scope, receive, send)
    |   File "D:\Elearning\learning\.venv\Lib\site-packages\starlette\_exception_handler.py", line 53, in wrapped_app
    |     raise exc
    |   File "D:\Elearning\learning\.venv\Lib\site-packages\starlette\_exception_handler.py", line 42, in wrapped_app
    |     await app(scope, receive, sender)
    |   File "D:\Elearning\learning\.venv\Lib\site-packages\starlette\routing.py", line 73, in app
    |     response = await f(request)
    |                ^^^^^^^^^^^^^^^^
    |   File "D:\Elearning\learning\.venv\Lib\site-packages\fastapi\routing.py", line 301, in app
    |     raw_response = await run_endpoint_function(
    |                    ^^^^^^^^^^^^^^^^^^^^^^^^^^^^
    |     ...<3 lines>...
    |     )
    |     ^
    |   File "D:\Elearning\learning\.venv\Lib\site-packages\fastapi\routing.py", line 212, in run_endpoint_function
    |     return await dependant.call(**values)
    |            ^^^^^^^^^^^^^^^^^^^^^^^^^^^^^^
    |   File "D:\Elearning\learning\routers\auth\auth.py", line 178, in login
    |     except (InvalidCredentialsException, ValidationException):
    |                                          ^^^^^^^^^^^^^^^^^^^
    | NameError: name 'ValidationException' is not defined
    +------------------------------------

During handling of the above exception, another exception occurred:

Traceback (most recent call last):
  File "D:\Elearning\learning\.venv\Lib\site-packages\starlette\middleware\errors.py", line 165, in __call__
    await self.app(scope, receive, _send)
  File "D:\Elearning\learning\.venv\Lib\site-packages\starlette\middleware\base.py", line 176, in __call__
    with recv_stream, send_stream, collapse_excgroups():
                                   ~~~~~~~~~~~~~~~~~~^^
  File "C:\Program Files\Python313\Lib\contextlib.py", line 162, in __exit__
    self.gen.throw(value)
    ~~~~~~~~~~~~~~^^^^^^^
  File "D:\Elearning\learning\.venv\Lib\site-packages\starlette\_utils.py", line 82, in collapse_excgroups
    raise exc
  File "D:\Elearning\learning\.venv\Lib\site-packages\starlette\middleware\base.py", line 178, in __call__
    response = await self.dispatch_func(request, call_next)
               ^^^^^^^^^^^^^^^^^^^^^^^^^^^^^^^^^^^^^^^^^^^^
  File "D:\Elearning\learning\middleware\logging_middleware.py", line 33, in dispatch
    response = await call_next(request)
               ^^^^^^^^^^^^^^^^^^^^^^^^
  File "D:\Elearning\learning\.venv\Lib\site-packages\starlette\middleware\base.py", line 156, in call_next
    raise app_exc
  File "D:\Elearning\learning\.venv\Lib\site-packages\starlette\middleware\base.py", line 141, in coro
    await self.app(scope, receive_or_disconnect, send_no_error)
  File "D:\Elearning\learning\.venv\Lib\site-packages\starlette\middleware\cors.py", line 93, in __call__
    await self.simple_response(scope, receive, send, request_headers=headers)
  File "D:\Elearning\learning\.venv\Lib\site-packages\starlette\middleware\cors.py", line 144, in simple_response
    await self.app(scope, receive, send)
  File "D:\Elearning\learning\.venv\Lib\site-packages\starlette\middleware\exceptions.py", line 62, in __call__
    await wrap_app_handling_exceptions(self.app, conn)(scope, receive, send)
  File "D:\Elearning\learning\.venv\Lib\site-packages\starlette\_exception_handler.py", line 53, in wrapped_app
    raise exc
  File "D:\Elearning\learning\.venv\Lib\site-packages\starlette\_exception_handler.py", line 42, in wrapped_app
    await app(scope, receive, sender)
  File "D:\Elearning\learning\.venv\Lib\site-packages\starlette\routing.py", line 714, in __call__
    await self.middleware_stack(scope, receive, send)
  File "D:\Elearning\learning\.venv\Lib\site-packages\starlette\routing.py", line 734, in app
    await route.handle(scope, receive, send)
  File "D:\Elearning\learning\.venv\Lib\site-packages\starlette\routing.py", line 288, in handle
    await self.app(scope, receive, send)
  File "D:\Elearning\learning\.venv\Lib\site-packages\starlette\routing.py", line 76, in app
    await wrap_app_handling_exceptions(app, request)(scope, receive, send)
  File "D:\Elearning\learning\.venv\Lib\site-packages\starlette\_exception_handler.py", line 53, in wrapped_app
    raise exc
  File "D:\Elearning\learning\.venv\Lib\site-packages\starlette\_exception_handler.py", line 42, in wrapped_app
    await app(scope, receive, sender)
  File "D:\Elearning\learning\.venv\Lib\site-packages\starlette\routing.py", line 73, in app
    response = await f(request)
               ^^^^^^^^^^^^^^^^
  File "D:\Elearning\learning\.venv\Lib\site-packages\fastapi\routing.py", line 301, in app
    raw_response = await run_endpoint_function(
                   ^^^^^^^^^^^^^^^^^^^^^^^^^^^^
    ...<3 lines>...
    )
    ^
  File "D:\Elearning\learning\.venv\Lib\site-packages\fastapi\routing.py", line 212, in run_endpoint_function
    return await dependant.call(**values)
           ^^^^^^^^^^^^^^^^^^^^^^^^^^^^^^
  File "D:\Elearning\learning\routers\auth\auth.py", line 178, in login
    except (InvalidCredentialsException, ValidationException):
                                         ^^^^^^^^^^^^^^^^^^^
NameError: name 'ValidationException' is not defined

2025-06-17 23:41:25 - errors - ERROR - ERROR AUTHENTICATION_ERROR: Invalid username or password | Info: Details: {'username': '123456akansh@gmail.com', 'reason': 'invalid_credentials'}
2025-06-17 23:41:55 - errors - ERROR - ERROR AUTHENTICATION_ERROR: Invalid username or password | Info: Details: {'username': 'akanshag', 'reason': 'invalid_credentials'}
2025-06-17 23:42:39 - errors - ERROR - ERROR AUTHENTICATION_ERROR: Invalid username or password | Info: Details: {'username': 'akanshag', 'reason': 'invalid_credentials'}
2025-06-17 23:43:21 - errors - ERROR - ERROR AUTHENTICATION_ERROR: Invalid username or password | Info: Details: {'username': 'akanshag', 'reason': 'invalid_credentials'}
2025-06-17 23:43:25 - errors - ERROR - ERROR AUTHENTICATION_ERROR: Invalid username or password | Info: Details: {'username': 'akanshag', 'reason': 'invalid_credentials'}
2025-06-17 23:45:18 - errors - ERROR - ERROR AUTHENTICATION_ERROR: Invalid username or password | Info: Details: {'username': '123456akansh@gmail.com', 'reason': 'invalid_credentials'}
2025-06-17 23:47:14 - errors - ERROR - ERROR VALIDATION_ERROR: Password does not meet strength requirements | Info: Details: {'field': 'password', 'value': '***'}
2025-06-17 23:48:07 - errors - ERROR - ERROR VALIDATION_ERROR: Password does not meet strength requirements | Info: Details: {'field': 'password', 'value': '***'}
2025-06-17 23:51:01 - errors - ERROR - ERROR AUTHENTICATION_ERROR: Invalid username or password | Info: Details: {'username': '123456akansh@gmail.com', 'reason': 'invalid_credentials'}
2025-06-17 23:51:10 - errors - ERROR - ERROR AUTHENTICATION_ERROR: Invalid username or password | Info: Details: {'username': '142akansh@gmail.com', 'reason': 'invalid_credentials'}
2025-06-17 23:51:12 - errors - ERROR - ERROR AUTHENTICATION_ERROR: Invalid username or password | Info: Details: {'username': '142akansh@gmail.com', 'reason': 'invalid_credentials'}
2025-06-17 23:51:19 - errors - ERROR - ERROR AUTHENTICATION_ERROR: Invalid username or password | Info: Details: {'username': '142akansh@gmail.com', 'reason': 'invalid_credentials'}
2025-06-17 23:52:06 - errors - ERROR - ERROR AUTHENTICATION_ERROR: Invalid username or password | Info: Details: {'username': '123456akansh@gmail.com', 'reason': 'invalid_credentials'}
2025-06-17 23:52:17 - errors - ERROR - ERROR AUTHENTICATION_ERROR: Invalid username or password | Info: Details: {'username': '142akansh@gmail.com', 'reason': 'invalid_credentials'}
2025-06-18 00:17:40 - errors - ERROR - ERROR VALIDATION_ERROR: User already exists with username: akansh | Info: Details: {'field': 'username', 'value': 'akansh'}
2025-06-18 00:18:29 - errors - ERROR - ERROR VALIDATION_ERROR: User already exists with username: akansh | Info: Details: {'field': 'username', 'value': 'akansh'}
2025-06-18 09:57:20 - errors - ERROR - ERROR AUTHENTICATION_ERROR: Invalid username or password | Info: Details: {'username': 'akanshag', 'reason': 'invalid_credentials'}
2025-06-18 10:01:04 - errors - ERROR - ERROR HTTP_ERROR: There was an error parsing the body | Info: Status: 400
2025-06-18 10:01:05 - errors - ERROR - ERROR BANNER_IMAGE_PROCESSING_FAILED: Image validation failed | User: 01dd0893-8008-4b0c-b85f-fe845899a142
2025-06-18 10:01:05 - errors - ERROR - ERROR VALIDATION_ERROR: Failed to process banner image | Info: Details: {'field': 'banner_image', 'value': {'error': 'Image validation failed'}}
2025-06-18 10:02:30 - errors - ERROR - ERROR VALIDATION_ERROR: Request validation failed | Info: Errors: [{'field': 'body', 'message': 'Input should be a valid dictionary or object to extract fields from', 'type': 'model_attributes_type'}]
2025-06-18 10:03:22 - errors - ERROR - ERROR VALIDATION_ERROR: Request validation failed | Info: Errors: [{'field': 'body -> banner_image', 'message': 'Field required', 'type': 'missing'}]
2025-06-18 10:03:26 - errors - ERROR - ERROR VALIDATION_ERROR: Request validation failed | Info: Errors: [{'field': 'body', 'message': 'Input should be a valid dictionary or object to extract fields from', 'type': 'model_attributes_type'}]
2025-06-18 10:22:10 - errors - ERROR - ERROR VALIDATION_ERROR: Request validation failed | Info: Errors: [{'field': 'body', 'message': 'Input should be a valid dictionary or object to extract fields from', 'type': 'model_attributes_type'}]
2025-06-18 10:22:33 - errors - ERROR - ERROR VALIDATION_ERROR: Request validation failed | Info: Errors: [{'field': 'body', 'message': 'Input should be a valid dictionary or object to extract fields from', 'type': 'model_attributes_type'}]
2025-06-18 10:22:37 - errors - ERROR - ERROR VALIDATION_ERROR: Request validation failed | Info: Errors: [{'field': 'body', 'message': 'Input should be a valid dictionary or object to extract fields from', 'type': 'model_attributes_type'}]
2025-06-18 10:22:52 - errors - ERROR - ERROR VALIDATION_ERROR: Request validation failed | Info: Errors: [{'field': 'body', 'message': 'Input should be a valid dictionary or object to extract fields from', 'type': 'model_attributes_type'}]
2025-06-18 15:41:29 - errors - ERROR - ERROR INTERNAL_SERVER_ERROR: Server not connected | Info: Traceback: Traceback (most recent call last):
  File "C:\Program Files\Python313\Lib\asyncio\selector_events.py", line 980, in _read_ready__get_buffer
    nbytes = self._sock.recv_into(buf)
ConnectionResetError: [WinError 10054] An existing connection was forcibly closed by the remote host

The above exception was the direct cause of the following exception:

Traceback (most recent call last):
  File "D:\Elearning\learning\.venv\Lib\site-packages\fastapi_mail\fastmail.py", line 153, in send_message
    await session.session.send_message(msg)
  File "D:\Elearning\learning\.venv\Lib\site-packages\aiosmtplib\smtp.py", line 1424, in send_message
    return await self.sendmail(
           ^^^^^^^^^^^^^^^^^^^^
    ...<6 lines>...
    )
    ^
  File "D:\Elearning\learning\.venv\Lib\site-packages\aiosmtplib\smtp.py", line 1299, in sendmail
    response = await self.data(message, timeout=timeout)
               ^^^^^^^^^^^^^^^^^^^^^^^^^^^^^^^^^^^^^^^^^
  File "D:\Elearning\learning\.venv\Lib\site-packages\aiosmtplib\smtp.py", line 881, in data
    return await self.protocol.execute_data_command(message, timeout=timeout)
           ^^^^^^^^^^^^^^^^^^^^^^^^^^^^^^^^^^^^^^^^^^^^^^^^^^^^^^^^^^^^^^^^^^
  File "D:\Elearning\learning\.venv\Lib\site-packages\aiosmtplib\protocol.py", line 321, in execute_data_command
    response = await self.read_response(timeout=timeout)
               ^^^^^^^^^^^^^^^^^^^^^^^^^^^^^^^^^^^^^^^^^
  File "D:\Elearning\learning\.venv\Lib\site-packages\aiosmtplib\protocol.py", line 252, in read_response
    result = await asyncio.wait_for(self._response_waiter, timeout)
             ^^^^^^^^^^^^^^^^^^^^^^^^^^^^^^^^^^^^^^^^^^^^^^^^^^^^^^
  File "C:\Program Files\Python313\Lib\asyncio\tasks.py", line 507, in wait_for
    return await fut
           ^^^^^^^^^
aiosmtplib.errors.SMTPServerDisconnected: Connection lost

During handling of the above exception, another exception occurred:

Traceback (most recent call last):
  File "D:\Elearning\learning\.venv\Lib\site-packages\starlette\middleware\errors.py", line 165, in __call__
    await self.app(scope, receive, _send)
  File "D:\Elearning\learning\.venv\Lib\site-packages\starlette\middleware\base.py", line 183, in __call__
    raise app_exc
  File "D:\Elearning\learning\.venv\Lib\site-packages\starlette\middleware\base.py", line 141, in coro
    await self.app(scope, receive_or_disconnect, send_no_error)
  File "D:\Elearning\learning\.venv\Lib\site-packages\starlette\middleware\cors.py", line 93, in __call__
    await self.simple_response(scope, receive, send, request_headers=headers)
  File "D:\Elearning\learning\.venv\Lib\site-packages\starlette\middleware\cors.py", line 144, in simple_response
    await self.app(scope, receive, send)
  File "D:\Elearning\learning\.venv\Lib\site-packages\starlette\middleware\exceptions.py", line 62, in __call__
    await wrap_app_handling_exceptions(self.app, conn)(scope, receive, send)
  File "D:\Elearning\learning\.venv\Lib\site-packages\starlette\_exception_handler.py", line 53, in wrapped_app
    raise exc
  File "D:\Elearning\learning\.venv\Lib\site-packages\starlette\_exception_handler.py", line 42, in wrapped_app
    await app(scope, receive, sender)
  File "D:\Elearning\learning\.venv\Lib\site-packages\starlette\routing.py", line 714, in __call__
    await self.middleware_stack(scope, receive, send)
  File "D:\Elearning\learning\.venv\Lib\site-packages\starlette\routing.py", line 734, in app
    await route.handle(scope, receive, send)
  File "D:\Elearning\learning\.venv\Lib\site-packages\starlette\routing.py", line 288, in handle
    await self.app(scope, receive, send)
  File "D:\Elearning\learning\.venv\Lib\site-packages\starlette\routing.py", line 76, in app
    await wrap_app_handling_exceptions(app, request)(scope, receive, send)
  File "D:\Elearning\learning\.venv\Lib\site-packages\starlette\_exception_handler.py", line 53, in wrapped_app
    raise exc
  File "D:\Elearning\learning\.venv\Lib\site-packages\starlette\_exception_handler.py", line 42, in wrapped_app
    await app(scope, receive, sender)
  File "D:\Elearning\learning\.venv\Lib\site-packages\starlette\routing.py", line 74, in app
    await response(scope, receive, send)
  File "D:\Elearning\learning\.venv\Lib\site-packages\starlette\responses.py", line 160, in __call__
    await self.background()
  File "D:\Elearning\learning\.venv\Lib\site-packages\starlette\background.py", line 41, in __call__
    await task()
  File "D:\Elearning\learning\.venv\Lib\site-packages\starlette\background.py", line 26, in __call__
    await self.func(*self.args, **self.kwargs)
  File "D:\Elearning\learning\services\emailservice.py", line 40, in send_welcome_email
    await fm.send_message(message)
  File "D:\Elearning\learning\.venv\Lib\site-packages\fastapi_mail\fastmail.py", line 151, in send_message
    async with Connection(self.config) as session:
               ~~~~~~~~~~^^^^^^^^^^^^^
  File "D:\Elearning\learning\.venv\Lib\site-packages\fastapi_mail\connection.py", line 31, in __aexit__
    await self.session.quit()
  File "D:\Elearning\learning\.venv\Lib\site-packages\aiosmtplib\smtp.py", line 780, in quit
    response = await self.execute_command(b"QUIT", timeout=timeout)
               ^^^^^^^^^^^^^^^^^^^^^^^^^^^^^^^^^^^^^^^^^^^^^^^^^^^^
  File "D:\Elearning\learning\.venv\Lib\site-packages\aiosmtplib\smtp.py", line 548, in execute_command
    response = await self.protocol.execute_command(
               ^^^^^^^^^^^^^^^^^^^^^^^^^^^^^^^^^^^^
        *args, timeout=self.timeout if timeout is _default else timeout
        ^^^^^^^^^^^^^^^^^^^^^^^^^^^^^^^^^^^^^^^^^^^^^^^^^^^^^^^^^^^^^^^
    )
    ^
  File "D:\Elearning\learning\.venv\Lib\site-packages\aiosmtplib\protocol.py", line 282, in execute_command
    raise SMTPServerDisconnected("Server not connected")
aiosmtplib.errors.SMTPServerDisconnected: Server not connected

2025-06-18 15:42:59 - errors - ERROR - ERROR INTERNAL_SERVER_ERROR: Server not connected | Info: Traceback: Traceback (most recent call last):
  File "C:\Program Files\Python313\Lib\asyncio\selector_events.py", line 980, in _read_ready__get_buffer
    nbytes = self._sock.recv_into(buf)
ConnectionResetError: [WinError 10054] An existing connection was forcibly closed by the remote host

The above exception was the direct cause of the following exception:

Traceback (most recent call last):
  File "D:\Elearning\learning\.venv\Lib\site-packages\fastapi_mail\fastmail.py", line 153, in send_message
    await session.session.send_message(msg)
  File "D:\Elearning\learning\.venv\Lib\site-packages\aiosmtplib\smtp.py", line 1424, in send_message
    return await self.sendmail(
           ^^^^^^^^^^^^^^^^^^^^
    ...<6 lines>...
    )
    ^
  File "D:\Elearning\learning\.venv\Lib\site-packages\aiosmtplib\smtp.py", line 1299, in sendmail
    response = await self.data(message, timeout=timeout)
               ^^^^^^^^^^^^^^^^^^^^^^^^^^^^^^^^^^^^^^^^^
  File "D:\Elearning\learning\.venv\Lib\site-packages\aiosmtplib\smtp.py", line 881, in data
    return await self.protocol.execute_data_command(message, timeout=timeout)
           ^^^^^^^^^^^^^^^^^^^^^^^^^^^^^^^^^^^^^^^^^^^^^^^^^^^^^^^^^^^^^^^^^^
  File "D:\Elearning\learning\.venv\Lib\site-packages\aiosmtplib\protocol.py", line 321, in execute_data_command
    response = await self.read_response(timeout=timeout)
               ^^^^^^^^^^^^^^^^^^^^^^^^^^^^^^^^^^^^^^^^^
  File "D:\Elearning\learning\.venv\Lib\site-packages\aiosmtplib\protocol.py", line 252, in read_response
    result = await asyncio.wait_for(self._response_waiter, timeout)
             ^^^^^^^^^^^^^^^^^^^^^^^^^^^^^^^^^^^^^^^^^^^^^^^^^^^^^^
  File "C:\Program Files\Python313\Lib\asyncio\tasks.py", line 507, in wait_for
    return await fut
           ^^^^^^^^^
aiosmtplib.errors.SMTPServerDisconnected: Connection lost

During handling of the above exception, another exception occurred:

Traceback (most recent call last):
  File "D:\Elearning\learning\.venv\Lib\site-packages\starlette\middleware\errors.py", line 165, in __call__
    await self.app(scope, receive, _send)
  File "D:\Elearning\learning\.venv\Lib\site-packages\starlette\middleware\base.py", line 183, in __call__
    raise app_exc
  File "D:\Elearning\learning\.venv\Lib\site-packages\starlette\middleware\base.py", line 141, in coro
    await self.app(scope, receive_or_disconnect, send_no_error)
  File "D:\Elearning\learning\.venv\Lib\site-packages\starlette\middleware\cors.py", line 93, in __call__
    await self.simple_response(scope, receive, send, request_headers=headers)
  File "D:\Elearning\learning\.venv\Lib\site-packages\starlette\middleware\cors.py", line 144, in simple_response
    await self.app(scope, receive, send)
  File "D:\Elearning\learning\.venv\Lib\site-packages\starlette\middleware\exceptions.py", line 62, in __call__
    await wrap_app_handling_exceptions(self.app, conn)(scope, receive, send)
  File "D:\Elearning\learning\.venv\Lib\site-packages\starlette\_exception_handler.py", line 53, in wrapped_app
    raise exc
  File "D:\Elearning\learning\.venv\Lib\site-packages\starlette\_exception_handler.py", line 42, in wrapped_app
    await app(scope, receive, sender)
  File "D:\Elearning\learning\.venv\Lib\site-packages\starlette\routing.py", line 714, in __call__
    await self.middleware_stack(scope, receive, send)
  File "D:\Elearning\learning\.venv\Lib\site-packages\starlette\routing.py", line 734, in app
    await route.handle(scope, receive, send)
  File "D:\Elearning\learning\.venv\Lib\site-packages\starlette\routing.py", line 288, in handle
    await self.app(scope, receive, send)
  File "D:\Elearning\learning\.venv\Lib\site-packages\starlette\routing.py", line 76, in app
    await wrap_app_handling_exceptions(app, request)(scope, receive, send)
  File "D:\Elearning\learning\.venv\Lib\site-packages\starlette\_exception_handler.py", line 53, in wrapped_app
    raise exc
  File "D:\Elearning\learning\.venv\Lib\site-packages\starlette\_exception_handler.py", line 42, in wrapped_app
    await app(scope, receive, sender)
  File "D:\Elearning\learning\.venv\Lib\site-packages\starlette\routing.py", line 74, in app
    await response(scope, receive, send)
  File "D:\Elearning\learning\.venv\Lib\site-packages\starlette\responses.py", line 160, in __call__
    await self.background()
  File "D:\Elearning\learning\.venv\Lib\site-packages\starlette\background.py", line 41, in __call__
    await task()
  File "D:\Elearning\learning\.venv\Lib\site-packages\starlette\background.py", line 26, in __call__
    await self.func(*self.args, **self.kwargs)
  File "D:\Elearning\learning\services\emailservice.py", line 40, in send_welcome_email
    await fm.send_message(message)
  File "D:\Elearning\learning\.venv\Lib\site-packages\fastapi_mail\fastmail.py", line 151, in send_message
    async with Connection(self.config) as session:
               ~~~~~~~~~~^^^^^^^^^^^^^
  File "D:\Elearning\learning\.venv\Lib\site-packages\fastapi_mail\connection.py", line 31, in __aexit__
    await self.session.quit()
  File "D:\Elearning\learning\.venv\Lib\site-packages\aiosmtplib\smtp.py", line 780, in quit
    response = await self.execute_command(b"QUIT", timeout=timeout)
               ^^^^^^^^^^^^^^^^^^^^^^^^^^^^^^^^^^^^^^^^^^^^^^^^^^^^
  File "D:\Elearning\learning\.venv\Lib\site-packages\aiosmtplib\smtp.py", line 548, in execute_command
    response = await self.protocol.execute_command(
               ^^^^^^^^^^^^^^^^^^^^^^^^^^^^^^^^^^^^
        *args, timeout=self.timeout if timeout is _default else timeout
        ^^^^^^^^^^^^^^^^^^^^^^^^^^^^^^^^^^^^^^^^^^^^^^^^^^^^^^^^^^^^^^^
    )
    ^
  File "D:\Elearning\learning\.venv\Lib\site-packages\aiosmtplib\protocol.py", line 282, in execute_command
    raise SMTPServerDisconnected("Server not connected")
aiosmtplib.errors.SMTPServerDisconnected: Server not connected

2025-06-18 15:58:48 - errors - ERROR - ERROR HTTP_ERROR: Not Found | Info: Status: 404
